```python
import logging
from typing import Callable, Any, Dict, Optional
import asyncio
from datetime import datetime
from prometheus_client import Counter, Histogram

logger = logging.getLogger(__name__)

# Retry metrics
retry_attempts = Counter(
    'linkedin_retry_attempts_total',
    'Total LinkedIn API retry attempts',
    ['operation']
)

retry_success = Counter(
    'linkedin_retry_success_total',
    'Successful LinkedIn API retries',
    ['operation']
)

retry_duration = Histogram(
    'linkedin_retry_duration_seconds',
    'LinkedIn API retry duration',
    ['operation']
)

class RetryHandler:
    def __init__(
        self,
        max_retries: int = 3,
        initial_delay: float = 1.0,
        max_delay: float = 10.0,
        exponential_base: float = 2.0
    ):
        self.max_retries = max_retries
        self.initial_delay = initial_delay
        self.max_delay = max_delay
        self.exponential_base = exponential_base

    async def execute_with_retry(
        self,
        operation: Callable,
        *args: Any,
        retry_on: Optional[tuple] = None,
        **kwargs: Any
    ) -> Any:
        """Execute an operation with retry logic."""
        if retry_on is None:
            retry_on = (Exception,)

        retries = 0
        operation_name = operation.__name__
        start_time = datetime.utcnow()

        while True:
            try:
                result = await operation(*args, **kwargs)
                if retries > 0:
                    retry_success.labels(operation=operation_name).inc()
                return result
                
            except retry_on as e:
                retries += 1
                retry_attempts.labels(operation=operation_name).inc()
                
                if retries >= self.max_retries:
                    logger.error(
                        f"Operation {operation_name} failed after "
                        f"{retries} retries: {str(e)}"
                    )
                    raise

                delay = self._calculate_delay(retries)
                logger.warning(
                    f"Operation {operation_name} failed (attempt {retries}), "
                    f"retrying in {delay:.2f}s: {str(e)}"
                )
                
                await asyncio.sleep(delay)
            finally:
                duration = (
                    datetime.utcnow() - start_time
                ).total_seconds()
                retry_duration.labels(
                    operation=operation_name
                ).observe(duration)

    def _calculate_delay(self, retry_count: int) -> float:
        """Calculate delay for next retry attempt."""
        delay = self.initial_delay * (
            self.exponential_base ** (retry_count - 1)
        )
        return min(delay, self.max_delay)

    async def execute_with_fallback(
        self,
        primary_operation: Callable,
        fallback_operation: Callable,
        *args: Any,
        **kwargs: Any
    ) -> Any:
        """Execute operation with fallback on failure."""
        try:
            return await self.execute_with_retry(
                primary_operation,
                *args,
                **kwargs
            )
        except Exception as e:
            logger.warning(
                f"Primary operation failed, using fallback: {str(e)}"
            )
            return await self.execute_with_retry(
                fallback_operation,
                *args,
                **kwargs
            )

    async def execute_batch_with_retry(
        self,
        operation: Callable,
        items: list,
        batch_size: int = 10,
        **kwargs: Any
    ) -> list:
        """Execute batch operation with retry logic."""
        results = []
        for i in range(0, len(items), batch_size):
            batch = items[i:i + batch_size]
            try:
                batch_results = await self.execute_with_retry(
                    operation,
                    batch,
                    **kwargs
                )
                results.extend(batch_results)
            except Exception as e:
                logger.error(f"Batch operation failed: {str(e)}")
                raise
        return results
```